<mujoco model="walker_165cm_65kg">
  <compiler angle="radian" coordinate="local" inertiafromgeom="false"/>
  <visual>
	    <scale framelength='0.5' framewidth='0.0075' forcewidth='0.0075' contactwidth='0.1' contactheight='0.01'/>
  </visual>
  <default>
    <joint armature="0.01" limited="true" />
    <motor ctrllimited="true" ctrlrange="-300 300" gear="1" forcelimited="true" forcerange="-300 300"/>
    <geom conaffinity="0" condim="3" contype="1" density="1000" friction=".7 .1 .1" rgba="0.8 0.6 .4 1"/>
  </default>
  <option integrator="RK4" timestep="0.001"/>
  <worldbody>
    <light cutoff="100" diffuse="1 1 1" dir="-0 0 -1.3" directional="true" exponent="1" pos="0 0 1.3" specular=".1 .1 .1"/>
    <geom conaffinity="1" condim="3" name="floor" pos="0 0 0" rgba="0.8 0.9 0.8 1" size="40 40 0.125" type="plane" material="MatPlane"/>
    <body name="pelvis" pos="0 0 1.035">
<!--  Uncomment to visualize the walker's COM position
      <geom name="COM" type="sphere" size="0.1" pos="0 0. 0" rgba="0 1 0 1"/>-->
      <inertial pos="0 0 0" mass="10.87" diaginertia="0.51 0.82 0.31"/>
      <geom friction="0.9" name="pelvis" size="0.05 0.1 0.04" pos="0 0 0.05" type="box"/>
      <camera name="track_pelvis" mode="trackcom" pos="0 -4 0" xyaxes="1 0 0 0 0 1"/>
      <joint name="pelvis_tx" armature="0" axis="1 0 0" damping="0" limited="false"  pos="0 0 0" stiffness="0" type="slide"/>
      <joint name="pelvis_tz" armature="0" axis="0 -1 0" damping="0" limited="false" pos="0 0 0" stiffness="0" type="slide"/>
      <joint name="pelvis_ty" armature="0" axis="0 0 1" damping="0" limited="false" pos="0 0 0" ref="1.035" stiffness="0" type="slide"/>
      <joint name="pelvis_list" armature="0" axis="1 0 0" damping="0" limited="false" pos="0 0 0" stiffness="0" type="hinge"/>
      <joint name="pelvis_tilt" armature="0" axis="0 -1 0" damping="0" limited="false" pos="0 0 0" stiffness="0" type="hinge"/>
      <joint name="pelvis_rotation" armature="0" axis="0 0 1" damping="0" limited="false" pos="0 0 0" stiffness="0" type="hinge"/>
      <body name="torso" pos="0 0 0.1075"> <!-- height of the pelvis + 2.5cm gap -->
        <inertial pos="0 0 0.2475" mass="32.5" diaginertia="1.875 3.0 1.125"/>
        <geom friction="0.9" name="torso" type="box" size="0.05 0.12 0.2475" pos="0 0 0.2475"/>
        <joint name="lumbar_bending" armature="0" axis="1 0 0" damping="0" range="-0.2 0.15" pos="0 0 0" stiffness="0" type="hinge"/>
        <joint name="lumbar_extension" armature="0" axis="0 -1 0" damping="0" range="-0.15 0.15" pos="0 0 0" stiffness="0" type="hinge"/>
        <joint name="lumbar_rotation" armature="0" axis="0 0 1" damping="0" range="-0.15 0.15" pos="0 0 0" stiffness="0" type="hinge"/>
      </body>
      <body name="thigh_right" pos="0 -0.08 0">
        <inertial pos="0 0 -0.2136" mass="6.9" diaginertia="0.122 0.122 0.024"/>
        <joint axis="0 -1 0" name="hip_flexion_r" damping="28" range="-0.8727 0.8727" type="hinge"/>
        <joint axis="1 0 0" name="hip_adduction_r" damping="28" range="-0.7854 0.0873" type="hinge"/>
        <joint axis="0 0 -1" name="hip_rotation_r" damping="28" range="-0.26 0.26" type="hinge"/>
        <geom friction="0.9" fromto="0 0 -0.05 0 0 -0.4272" name="thigh_geom" size="0.05" type="capsule"/>
        <body name="shank_right" pos="0 0 -0.4772">
          <inertial pos="0 0 -0.2136" mass="2.8" diaginertia="0.04 0.04 0.0024"/>
          <joint axis="0 -1 0" name="knee_angle_r" damping="12" range="-2.6180 0." type="hinge"/>
          <geom friction="0.9" fromto="0 0 -0.05 0 0 -0.4272" name="leg_geom" size="0.04" type="capsule"/>
          <body name="foot_right" pos="0 0 -0.4772">
            <inertial pos="0.06 0 -0.07" mass="1.2" diaginertia="0.003 0.006 0.005"/>
            <joint axis="0 1 0" name="ankle_angle_r" damping="20"  range="-0.3491 0.6981" type="hinge"/>
            <geom friction="0.9" axisangle="0 0 1 -.05" name="right_foot" size="0.11 0.05 0.04" pos="0.0675 -0.005 -0.04" type="box"/>
<!--            <geom friction="0.9" fromto="0 0 -0.04 0.2 0 -0.04" name="foot_geom" size="0.05" type="capsule"/>-->
            <site name='right_foot_front_left' type="sphere" size="0.005" pos="0.1775 0.04 -0.08" rgba="0 0 .99 0.5" />
            <site name='right_foot_front_right' type="sphere" size="0.005" pos="0.1775 -0.06 -0.08" rgba="0 0 .99 0.5" />
            <site name='right_foot_back_left' type="sphere" size="0.005" pos="-0.0425 0.05 -0.08" rgba="0 0 .99 0.5" />
            <site name='right_foot_back_right' type="sphere" size="0.005" pos="-0.0425 -0.05 -0.08" rgba="0 0 .99 0.5" />
          </body>
        </body>
      </body>
      <!-- copied and then replace thigh->thigh_left, leg->leg_left, foot->foot_right -->
      <body name="thigh_left" pos="0 0.08 0">
        <inertial pos="0 0 -0.2136" mass="6.9" diaginertia="0.122 0.122 0.024"/>
        <joint axis="0 -1 0" name="hip_flexion_l" damping="28" range="-0.8727 0.8727" type="hinge"/>
        <joint axis="-1 0 0" name="hip_adduction_l" damping="28" range="-0.7854 0.0873" type="hinge"/>
        <joint axis="0 0 -1" name="hip_rotation_l" damping="28" range="-0.26 0.26" type="hinge"/>
        <geom friction="0.9" fromto="0 0 -0.05 0 0 -0.4272" name="thigh_left_geom" rgba=".7 .3 .6 1" size="0.05" type="capsule"/>
        <body name="shank_left" pos="0 0 -0.4772">
          <inertial pos="0 0 -0.2136" mass="2.8" diaginertia="0.04 0.04 0.0024"/>
          <joint axis="0 -1 0" name="knee_angle_l" damping="12" range="-2.6180 0."  type="hinge"/>
          <geom friction="0.9" fromto="0 0 -0.05 0 0 -0.45" name="leg_left_geom" rgba=".7 .3 .6 1" size="0.04" type="capsule"/>
          <body name="foot_left" pos="0 0 -0.4772">
            <inertial pos="0.06 0 -0.07" mass="1.2" diaginertia="0.003 0.006 0.005"/>
            <joint axis="0 -1 0" name="ankle_angle_l" damping="20" range="-0.6981 0.3491" type="hinge"/>
            <geom friction="0.9" axisangle="0 0 1 .05" name="left_foot" size="0.11 0.05 0.04" pos="0.0675 0.005 -0.04" rgba=".7 .3 .6 1" type="box"/>
<!--            <geom friction="1.9" fromto="0 0 -0.04 0.2 0 -0.04" name="foot_left_geom" rgba=".7 .3 .6 1" size="0.05" type="capsule"/>-->
            <site name='left_foot_front_left' type="sphere" size="0.005" pos="0.1775 0.06 -0.08" rgba="0 0 .99 0.5" />
            <site name='left_foot_front_right' type="sphere" size="0.005" pos="0.1775 -0.04 -0.08" rgba="0 0 .99 0.5" />
            <site name='left_foot_back_left' type="sphere" size="0.005" pos="-0.0425 0.05 -0.08" rgba="0 0 .99 0.5" />
            <site name='left_foot_back_right' type="sphere" size="0.005" pos="-0.0425 -0.05 -0.08" rgba="0 0 .99 0.5" />
          </body>
        </body>
      </body>
    </body>
  </worldbody>
  <actuator>
    <motor joint="lumbar_extension"/>
    <motor joint="lumbar_bending"/>
    <motor joint="lumbar_rotation"/>
    <motor joint="hip_flexion_r"/>
    <motor joint="hip_adduction_r"/>
    <motor joint="hip_rotation_r"/>
    <motor joint="knee_angle_r"/>
    <motor joint="ankle_angle_r"/>
    <motor joint="hip_flexion_l"/>
    <motor joint="hip_adduction_l"/>
    <motor joint="hip_rotation_l"/>
    <motor joint="knee_angle_l"/>
    <motor joint="ankle_angle_l"/>
  </actuator>
    <asset>
        <texture type="skybox" builtin="gradient" rgb1=".4 .5 .6" rgb2="0 0 0"
            width="100" height="100"/>
        <texture builtin="flat" height="1278" mark="cross" markrgb="1 1 1" name="texgeom" random="0.01" rgb1="0.8 0.6 0.4" rgb2="0.8 0.6 0.4" type="cube" width="127"/>
        <texture builtin="checker" height="100" name="texplane" rgb1="0 0 0" rgb2="0.8 0.8 0.8" type="2d" width="100"/>
        <material name="MatPlane" reflectance="0.5" shininess="1" specular="1" texrepeat="60 60" texture="texplane"/>
        <material name="geom" texture="texgeom" texuniform="true"/>
    </asset>
</mujoco>
